Workbook

Sheet Calculator
A1: COD Profit Calculator - COD Network
A2: YELLOW = type your numbers here | B2: RED = key costs | C2: GREEN = revenue & profit | E2: BLUE = break-even
A3: No color = calculated automatically (don't type there). Fees come from the 'COD Network Fees' tab.
A4: 1. INPUTS | E4: 2. OFFERS - price, delivery fee and share of orders for each offer
A5: Market (country) | B5: Morocco | C5: Pick from the list | E5: Enter the product price, the delivery fee you charge the customer, and the % of orders that choose each offer. Free units are counted as product cost. Profit columns = "if every order took this offer". | S5: Helper per offer (do not edit)
A6: Product category | B6: Gadget | C6: Gadget or Cosmetic (changes call-center fees in GCC) | E6: Offer | F6: Paid units | G6: Free units | H6: Units per order | I6: Product price | J6: Delivery fee charged to customer | K6: Customer pays (price + delivery) | L6: % of orders | M6: Product cost per order | N6: Net profit per delivered order | O6: Net profit (if all orders) | P6: Break-even cost per lead | Q6: Net profit per unit delivered | S6: Overweight / order | T6: alpha | U6: beta | V6: gamma
A7: Use COD Network call center? | B7: Yes | C7: No = you confirm orders yourself (no call-center fees) | E7: Buy 1 | F7: 1 | G7: 0 | H7: =F7+G7 -> 1 | I7: 249 | J7: 30 | K7: =I7+J7 -> 279 | L7: 0.5 | M7: =H7*$B$9 -> 40 | N7: =IF($B$41=0,0,O7/$B$41) -> 117.21333 | O7: =$B$12*((1-$B$19)*(-$B$26+$B$13*(1-$B$14)*T7+$B$13*$B$14*U7)-$B$13*(1-$B$14)*V7-$B$36)-$B$20 -> 45713.2 | P7: =IF($B$12=0,0,(O7+$B$59)/$B$12/IF($B$11="USD",$B$35,1)) -> 6.9688261 | Q7: =IF(H7=0,0,N7/H7) -> 117.21333 | S7: =MAX(0,H7*$B$18-5)*INDEX('COD Network Fees'!$O$5:$O$23,$B$23) -> 0 | T7: =(K7+$B$15*$B$16)*(1-$B$34)-$B$27-$B$28-$B$15*$B$29-$B$30-$B$32-S7 -> 225 | U7: =-($B$27+$B$31+$B$32+S7) -> -21 | V7: =H7*$B$9+$B$15*$B$17 -> 40
A8: Average order value (price + delivery fee) | B8: =IF(SUM($L$7:$L$9)=0,0,SUMPRODUCT($K$7:$K$9,$L$7:$L$9)/SUM($L$7:$L$9)) -> 334 | C8: Calculated from the OFFERS table on the right (what the customer pays x mix) | E8: Buy 1 Get 1 Free | F8: 1 | G8: 1 | H8: =F8+G8 -> 2 | I8: 349 | J8: 0 | K8: =I8+J8 -> 349 | L8: 0.3 | M8: =H8*$B$9 -> 80 | N8: =IF($B$41=0,0,O8/$B$41) -> 145.81333 | O8: =$B$12*((1-$B$19)*(-$B$26+$B$13*(1-$B$14)*T8+$B$13*$B$14*U8)-$B$13*(1-$B$14)*V8-$B$36)-$B$20 -> 56867.2 | P8: =IF($B$12=0,0,(O8+$B$59)/$B$12/IF($B$11="USD",$B$35,1)) -> 8.1812174 | Q8: =IF(H8=0,0,N8/H8) -> 72.906667 | S8: =MAX(0,H8*$B$18-5)*INDEX('COD Network Fees'!$O$5:$O$23,$B$23) -> 0 | T8: =(K8+$B$15*$B$16)*(1-$B$34)-$B$27-$B$28-$B$15*$B$29-$B$30-$B$32-S8 -> 295 | U8: =-($B$27+$B$31+$B$32+S8) -> -21 | V8: =H8*$B$9+$B$15*$B$17 -> 80
A9: Product cost (landed, per unit) | B9: 40 | C9: ="Purchase + import cost per unit, in "&B25&" (free units count too)" -> Purchase + import cost per unit, in MAD (free units count too) | E9: Buy 2 Get 1 Free | F9: 2 | G9: 1 | H9: =F9+G9 -> 3 | I9: 449 | J9: 0 | K9: =I9+J9 -> 449 | L9: 0.2 | M9: =H9*$B$9 -> 120 | N9: =IF($B$41=0,0,O9/$B$41) -> 203.81333 | O9: =$B$12*((1-$B$19)*(-$B$26+$B$13*(1-$B$14)*T9+$B$13*$B$14*U9)-$B$13*(1-$B$14)*V9-$B$36)-$B$20 -> 79487.2 | P9: =IF($B$12=0,0,(O9+$B$59)/$B$12/IF($B$11="USD",$B$35,1)) -> 10.639913 | Q9: =IF(H9=0,0,N9/H9) -> 67.937778 | S9: =MAX(0,H9*$B$18-5)*INDEX('COD Network Fees'!$O$5:$O$23,$B$23) -> 0 | T9: =(K9+$B$15*$B$16)*(1-$B$34)-$B$27-$B$28-$B$15*$B$29-$B$30-$B$32-S9 -> 395 | U9: =-($B$27+$B$31+$B$32+S9) -> -21 | V9: =H9*$B$9+$B$15*$B$17 -> 120
A10: Cost per result (cost per lead) | B10: 2 | C10: From your ads manager | E10: Your mix (weighted) | H10: =IF(SUM($L$7:$L$9)=0,0,SUMPRODUCT(H7:H9,$L$7:$L$9)/SUM($L$7:$L$9)) -> 1.7 | I10: =IF(SUM($L$7:$L$9)=0,0,SUMPRODUCT(I7:I9,$L$7:$L$9)/SUM($L$7:$L$9)) -> 319 | J10: =IF(SUM($L$7:$L$9)=0,0,SUMPRODUCT(J7:J9,$L$7:$L$9)/SUM($L$7:$L$9)) -> 15 | K10: =$B$8 -> 334 | L10: =SUM(L7:L9) -> 1 | M10: =H10*$B$9 -> 68 | N10: =$B$66 -> 143.11333 | O10: =$B$63 -> 55814.2 | P10: =$B$73 -> 8.0667609 | Q10: =$B$67 -> 84.184314
A11: Cost per result is in | B11: USD | C11: USD or Market currency | E11: =IF(ROUND(L10,4)=1,"Offer shares add up to 100%.","Warning: offer shares add up to "&TEXT(L10,"0%")&" - they are scaled to 100% in the calculations.") -> Offer shares add up to 100%.
A12: Number of leads | B12: 1000 | C12: Leads / orders received in the period | E12: ="Customers pay the delivery fee only on delivered orders. COD Network's shipping cost is still charged to you. Currency: "&$B$25 -> Customers pay the delivery fee only on delivered orders. COD Network's shipping cost is still charged to you. Currency: MAD | S12: Helper: per-lead model (do not edit)
A13: Confirmation rate | B13: 0.6 | C13: % of leads confirmed by the call center | S13: Cash per delivered (incl. upsell) | T13: =B8+B15*B16 -> 334
A14: Return rate | B14: 0.35 | C14: % of confirmed orders refused / not delivered | E14: 7. NET PROFIT SENSITIVITY: cost per lead (rows) x return rate (columns) | S14: alpha (per delivered) | T14: =T13*(1-B34)-B27-B28-B15*B29-B30-B32-B33 -> 280
A15: Upsell rate | B15: 0 | C15: % of delivered orders that took an upsell / cross-sell | E15: ="Uses your offer mix, confirmation rate and fees. CPL in "&IF($B$11="USD","USD",$B$25)&", profit in "&$B$25&"." -> Uses your offer mix, confirmation rate and fees. CPL in USD, profit in MAD. | S15: beta (per returned) | T15: =-(B27+B31+B32+B33) -> -21
A16: Upsell extra revenue per upsell | B16: 0 | C16: Extra price collected per upsell order | E16: CPL \ Return | F16: 0.15 | G16: 0.25 | H16: 0.3 | I16: 0.35 | J16: 0.4 | K16: 0.5 | L16: 0.6 | S16: gamma (product cost per delivered) | T16: =H10*B9+B15*B17 -> 68
A17: Upsell extra product cost per upsell | B17: 0 | C17: Extra unit cost per upsell order | E17: =$B$10*0.5 -> 1 | F17: =$B$12*((1-$B$19)*(-$T$17+$B$13*(1-F$16)*$T$14+$B$13*F$16*$T$15)-$B$13*(1-F$16)*$T$16-$E17*IF($B$11="USD",$B$35,1))-$B$20 -> 92251.8 | G17: =$B$12*((1-$B$19)*(-$T$17+$B$13*(1-G$16)*$T$14+$B$13*G$16*$T$15)-$B$13*(1-G$16)*$T$16-$E17*IF($B$11="USD",$B$35,1))-$B$20 -> 78633 | H17: =$B$12*((1-$B$19)*(-$T$17+$B$13*(1-H$16)*$T$14+$B$13*H$16*$T$15)-$B$13*(1-H$16)*$T$16-$E17*IF($B$11="USD",$B$35,1))-$B$20 -> 71823.6 | I17: =$B$12*((1-$B$19)*(-$T$17+$B$13*(1-I$16)*$T$14+$B$13*I$16*$T$15)-$B$13*(1-I$16)*$T$16-$E17*IF($B$11="USD",$B$35,1))-$B$20 -> 65014.2 | J17: =$B$12*((1-$B$19)*(-$T$17+$B$13*(1-J$16)*$T$14+$B$13*J$16*$T$15)-$B$13*(1-J$16)*$T$16-$E17*IF($B$11="USD",$B$35,1))-$B$20 -> 58204.8 | K17: =$B$12*((1-$B$19)*(-$T$17+$B$13*(1-K$16)*$T$14+$B$13*K$16*$T$15)-$B$13*(1-K$16)*$T$16-$E17*IF($B$11="USD",$B$35,1))-$B$20 -> 44586 | L17: =$B$12*((1-$B$19)*(-$T$17+$B$13*(1-L$16)*$T$14+$B$13*L$16*$T$15)-$B$13*(1-L$16)*$T$16-$E17*IF($B$11="USD",$B$35,1))-$B$20 -> 30967.2 | S17: Lead fee | T17: =B26 -> 2
A18: Weight per unit (kg) | B18: 0.5 | C18: Higher of real or volumetric (LxHxW/5000); order weight = units x this | E18: =$B$10*0.75 -> 1.5 | F18: =$B$12*((1-$B$19)*(-$T$17+$B$13*(1-F$16)*$T$14+$B$13*F$16*$T$15)-$B$13*(1-F$16)*$T$16-$E18*IF($B$11="USD",$B$35,1))-$B$20 -> 87651.8 | G18: =$B$12*((1-$B$19)*(-$T$17+$B$13*(1-G$16)*$T$14+$B$13*G$16*$T$15)-$B$13*(1-G$16)*$T$16-$E18*IF($B$11="USD",$B$35,1))-$B$20 -> 74033 | H18: =$B$12*((1-$B$19)*(-$T$17+$B$13*(1-H$16)*$T$14+$B$13*H$16*$T$15)-$B$13*(1-H$16)*$T$16-$E18*IF($B$11="USD",$B$35,1))-$B$20 -> 67223.6 | I18: =$B$12*((1-$B$19)*(-$T$17+$B$13*(1-I$16)*$T$14+$B$13*I$16*$T$15)-$B$13*(1-I$16)*$T$16-$E18*IF($B$11="USD",$B$35,1))-$B$20 -> 60414.2 | J18: =$B$12*((1-$B$19)*(-$T$17+$B$13*(1-J$16)*$T$14+$B$13*J$16*$T$15)-$B$13*(1-J$16)*$T$16-$E18*IF($B$11="USD",$B$35,1))-$B$20 -> 53604.8 | K18: =$B$12*((1-$B$19)*(-$T$17+$B$13*(1-K$16)*$T$14+$B$13*K$16*$T$15)-$B$13*(1-K$16)*$T$16-$E18*IF($B$11="USD",$B$35,1))-$B$20 -> 39986 | L18: =$B$12*((1-$B$19)*(-$T$17+$B$13*(1-L$16)*$T$14+$B$13*L$16*$T$15)-$B$13*(1-L$16)*$T$16-$E18*IF($B$11="USD",$B$35,1))-$B$20 -> 26367.2 | S18: Fixed per lead | T18: =IF(B12=0,0,B20/B12) -> 0
A19: Payment processing fee (on payout) | B19: 0.02 | C19: Contract: 0% to 5% by method (PayPal, bank, Payoneer) | E19: =$B$10*1 -> 2 | F19: =$B$12*((1-$B$19)*(-$T$17+$B$13*(1-F$16)*$T$14+$B$13*F$16*$T$15)-$B$13*(1-F$16)*$T$16-$E19*IF($B$11="USD",$B$35,1))-$B$20 -> 83051.8 | G19: =$B$12*((1-$B$19)*(-$T$17+$B$13*(1-G$16)*$T$14+$B$13*G$16*$T$15)-$B$13*(1-G$16)*$T$16-$E19*IF($B$11="USD",$B$35,1))-$B$20 -> 69433 | H19: =$B$12*((1-$B$19)*(-$T$17+$B$13*(1-H$16)*$T$14+$B$13*H$16*$T$15)-$B$13*(1-H$16)*$T$16-$E19*IF($B$11="USD",$B$35,1))-$B$20 -> 62623.6 | I19: =$B$12*((1-$B$19)*(-$T$17+$B$13*(1-I$16)*$T$14+$B$13*I$16*$T$15)-$B$13*(1-I$16)*$T$16-$E19*IF($B$11="USD",$B$35,1))-$B$20 -> 55814.2 | J19: =$B$12*((1-$B$19)*(-$T$17+$B$13*(1-J$16)*$T$14+$B$13*J$16*$T$15)-$B$13*(1-J$16)*$T$16-$E19*IF($B$11="USD",$B$35,1))-$B$20 -> 49004.8 | K19: =$B$12*((1-$B$19)*(-$T$17+$B$13*(1-K$16)*$T$14+$B$13*K$16*$T$15)-$B$13*(1-K$16)*$T$16-$E19*IF($B$11="USD",$B$35,1))-$B$20 -> 35386 | L19: =$B$12*((1-$B$19)*(-$T$17+$B$13*(1-L$16)*$T$14+$B$13*L$16*$T$15)-$B$13*(1-L$16)*$T$16-$E19*IF($B$11="USD",$B$35,1))-$B$20 -> 21767.2 | S19: Intercept (r=0, total) | T19: =B12*((1-B19)*(-T17+B13*T14)-B13*T16-B36-T18) -> 103480
A20: Other fixed costs (period) | B20: 0 | C20: Shopify, apps, creatives, salaries, customs... in market currency | E20: =$B$10*1.25 -> 2.5 | F20: =$B$12*((1-$B$19)*(-$T$17+$B$13*(1-F$16)*$T$14+$B$13*F$16*$T$15)-$B$13*(1-F$16)*$T$16-$E20*IF($B$11="USD",$B$35,1))-$B$20 -> 78451.8 | G20: =$B$12*((1-$B$19)*(-$T$17+$B$13*(1-G$16)*$T$14+$B$13*G$16*$T$15)-$B$13*(1-G$16)*$T$16-$E20*IF($B$11="USD",$B$35,1))-$B$20 -> 64833 | H20: =$B$12*((1-$B$19)*(-$T$17+$B$13*(1-H$16)*$T$14+$B$13*H$16*$T$15)-$B$13*(1-H$16)*$T$16-$E20*IF($B$11="USD",$B$35,1))-$B$20 -> 58023.6 | I20: =$B$12*((1-$B$19)*(-$T$17+$B$13*(1-I$16)*$T$14+$B$13*I$16*$T$15)-$B$13*(1-I$16)*$T$16-$E20*IF($B$11="USD",$B$35,1))-$B$20 -> 51214.2 | J20: =$B$12*((1-$B$19)*(-$T$17+$B$13*(1-J$16)*$T$14+$B$13*J$16*$T$15)-$B$13*(1-J$16)*$T$16-$E20*IF($B$11="USD",$B$35,1))-$B$20 -> 44404.8 | K20: =$B$12*((1-$B$19)*(-$T$17+$B$13*(1-K$16)*$T$14+$B$13*K$16*$T$15)-$B$13*(1-K$16)*$T$16-$E20*IF($B$11="USD",$B$35,1))-$B$20 -> 30786 | L20: =$B$12*((1-$B$19)*(-$T$17+$B$13*(1-L$16)*$T$14+$B$13*L$16*$T$15)-$B$13*(1-L$16)*$T$16-$E20*IF($B$11="USD",$B$35,1))-$B$20 -> 17167.2 | S20: Slope per unit return rate | T20: =B12*B13*((1-B19)*(T15-T14)+T16) -> -136188
E21: =$B$10*1.5 -> 3 | F21: =$B$12*((1-$B$19)*(-$T$17+$B$13*(1-F$16)*$T$14+$B$13*F$16*$T$15)-$B$13*(1-F$16)*$T$16-$E21*IF($B$11="USD",$B$35,1))-$B$20 -> 73851.8 | G21: =$B$12*((1-$B$19)*(-$T$17+$B$13*(1-G$16)*$T$14+$B$13*G$16*$T$15)-$B$13*(1-G$16)*$T$16-$E21*IF($B$11="USD",$B$35,1))-$B$20 -> 60233 | H21: =$B$12*((1-$B$19)*(-$T$17+$B$13*(1-H$16)*$T$14+$B$13*H$16*$T$15)-$B$13*(1-H$16)*$T$16-$E21*IF($B$11="USD",$B$35,1))-$B$20 -> 53423.6 | I21: =$B$12*((1-$B$19)*(-$T$17+$B$13*(1-I$16)*$T$14+$B$13*I$16*$T$15)-$B$13*(1-I$16)*$T$16-$E21*IF($B$11="USD",$B$35,1))-$B$20 -> 46614.2 | J21: =$B$12*((1-$B$19)*(-$T$17+$B$13*(1-J$16)*$T$14+$B$13*J$16*$T$15)-$B$13*(1-J$16)*$T$16-$E21*IF($B$11="USD",$B$35,1))-$B$20 -> 39804.8 | K21: =$B$12*((1-$B$19)*(-$T$17+$B$13*(1-K$16)*$T$14+$B$13*K$16*$T$15)-$B$13*(1-K$16)*$T$16-$E21*IF($B$11="USD",$B$35,1))-$B$20 -> 26186 | L21: =$B$12*((1-$B$19)*(-$T$17+$B$13*(1-L$16)*$T$14+$B$13*L$16*$T$15)-$B$13*(1-L$16)*$T$16-$E21*IF($B$11="USD",$B$35,1))-$B$20 -> 12567.2 | S21: Check: model - P&L (should be 0) | T21: =ROUND(T19+T20*B14-B63,6) -> 0
A22: 3. FEES APPLIED (pulled automatically from your contract) | E22: =$B$10*2 -> 4 | F22: =$B$12*((1-$B$19)*(-$T$17+$B$13*(1-F$16)*$T$14+$B$13*F$16*$T$15)-$B$13*(1-F$16)*$T$16-$E22*IF($B$11="USD",$B$35,1))-$B$20 -> 64651.8 | G22: =$B$12*((1-$B$19)*(-$T$17+$B$13*(1-G$16)*$T$14+$B$13*G$16*$T$15)-$B$13*(1-G$16)*$T$16-$E22*IF($B$11="USD",$B$35,1))-$B$20 -> 51033 | H22: =$B$12*((1-$B$19)*(-$T$17+$B$13*(1-H$16)*$T$14+$B$13*H$16*$T$15)-$B$13*(1-H$16)*$T$16-$E22*IF($B$11="USD",$B$35,1))-$B$20 -> 44223.6 | I22: =$B$12*((1-$B$19)*(-$T$17+$B$13*(1-I$16)*$T$14+$B$13*I$16*$T$15)-$B$13*(1-I$16)*$T$16-$E22*IF($B$11="USD",$B$35,1))-$B$20 -> 37414.2 | J22: =$B$12*((1-$B$19)*(-$T$17+$B$13*(1-J$16)*$T$14+$B$13*J$16*$T$15)-$B$13*(1-J$16)*$T$16-$E22*IF($B$11="USD",$B$35,1))-$B$20 -> 30604.8 | K22: =$B$12*((1-$B$19)*(-$T$17+$B$13*(1-K$16)*$T$14+$B$13*K$16*$T$15)-$B$13*(1-K$16)*$T$16-$E22*IF($B$11="USD",$B$35,1))-$B$20 -> 16986 | L22: =$B$12*((1-$B$19)*(-$T$17+$B$13*(1-L$16)*$T$14+$B$13*L$16*$T$15)-$B$13*(1-L$16)*$T$16-$E22*IF($B$11="USD",$B$35,1))-$B$20 -> 3367.2 | S22: Check: offer mix - P&L (should be 0) | T22: =ROUND(IF(L10=0,0,SUMPRODUCT(O7:O9,L7:L9)/L10)-B63,6) -> 0
A23: Fee table row (helper) | B23: =MATCH(B5,'COD Network Fees'!$A$5:$A$23,0) -> 7 | C23: Position of the market in the fee table | E23: =$B$10*2.5 -> 5 | F23: =$B$12*((1-$B$19)*(-$T$17+$B$13*(1-F$16)*$T$14+$B$13*F$16*$T$15)-$B$13*(1-F$16)*$T$16-$E23*IF($B$11="USD",$B$35,1))-$B$20 -> 55451.8 | G23: =$B$12*((1-$B$19)*(-$T$17+$B$13*(1-G$16)*$T$14+$B$13*G$16*$T$15)-$B$13*(1-G$16)*$T$16-$E23*IF($B$11="USD",$B$35,1))-$B$20 -> 41833 | H23: =$B$12*((1-$B$19)*(-$T$17+$B$13*(1-H$16)*$T$14+$B$13*H$16*$T$15)-$B$13*(1-H$16)*$T$16-$E23*IF($B$11="USD",$B$35,1))-$B$20 -> 35023.6 | I23: =$B$12*((1-$B$19)*(-$T$17+$B$13*(1-I$16)*$T$14+$B$13*I$16*$T$15)-$B$13*(1-I$16)*$T$16-$E23*IF($B$11="USD",$B$35,1))-$B$20 -> 28214.2 | J23: =$B$12*((1-$B$19)*(-$T$17+$B$13*(1-J$16)*$T$14+$B$13*J$16*$T$15)-$B$13*(1-J$16)*$T$16-$E23*IF($B$11="USD",$B$35,1))-$B$20 -> 21404.8 | K23: =$B$12*((1-$B$19)*(-$T$17+$B$13*(1-K$16)*$T$14+$B$13*K$16*$T$15)-$B$13*(1-K$16)*$T$16-$E23*IF($B$11="USD",$B$35,1))-$B$20 -> 7786 | L23: =$B$12*((1-$B$19)*(-$T$17+$B$13*(1-L$16)*$T$14+$B$13*L$16*$T$15)-$B$13*(1-L$16)*$T$16-$E23*IF($B$11="USD",$B$35,1))-$B$20 -> -5832.8
A24: Region | B24: =INDEX('COD Network Fees'!$B$5:$B$23,$B$23) -> Morocco | E24: Rows = 0.5x to 2.5x your current cost per lead. Yellow return rates can be changed. Red = loss, green = profit.
A25: Currency | B25: =INDEX('COD Network Fees'!$C$5:$C$23,$B$23) -> MAD | C25: All amounts below are in this currency
A26: Call center - fee per lead | B26: =IF($B$7="Yes",IF($B$6="Cosmetic",INDEX('COD Network Fees'!$G$5:$G$23,$B$23),INDEX('COD Network Fees'!$D$5:$D$23,$B$23)),0) -> 2
A27: Call center - fee per confirmed order | B27: =IF($B$7="Yes",IF($B$6="Cosmetic",INDEX('COD Network Fees'!$H$5:$H$23,$B$23),INDEX('COD Network Fees'!$E$5:$E$23,$B$23)),0) -> 4
A28: Call center - fee per delivered order | B28: =IF($B$7="Yes",IF($B$6="Cosmetic",INDEX('COD Network Fees'!$I$5:$I$23,$B$23),INDEX('COD Network Fees'!$F$5:$F$23,$B$23)),0) -> 7
A29: Call center - fee per upsell | B29: =IF($B$7="Yes",INDEX('COD Network Fees'!$J$5:$J$23,$B$23),0) -> 5
A30: Shipping per delivered order | B30: =IF(AND($B$7="No",INDEX('COD Network Fees'!$M$5:$M$23,$B$23)<>""),INDEX('COD Network Fees'!$M$5:$M$23,$B$23),INDEX('COD Network Fees'!$K$5:$K$23,$B$23)) -> 35 | C30: Without call center the flat GCC rate is used
A31: Shipping per returned order | B31: =IF(AND($B$7="No",INDEX('COD Network Fees'!$M$5:$M$23,$B$23)<>""),INDEX('COD Network Fees'!$M$5:$M$23,$B$23),INDEX('COD Network Fees'!$L$5:$L$23,$B$23)) -> 9
A32: Fulfillment per shipped order | B32: =INDEX('COD Network Fees'!$N$5:$N$23,$B$23) -> 8 | C32: Charged on every shipped (confirmed) order
A33: Overweight surcharge per shipped order (avg) | B33: =IF(SUM($L$7:$L$9)=0,0,SUMPRODUCT($S$7:$S$9,$L$7:$L$9)/SUM($L$7:$L$9)) -> 0 | C33: Contract: +1 per kg above 5 kg (local shipping), weighted by offer mix
A34: COD fee (% of cash collected) | B34: =INDEX('COD Network Fees'!$P$5:$P$23,$B$23) -> 0
A35: Exchange rate (units per 1 USD) | B35: =INDEX('COD Network Fees'!$B$27:$B$29,MATCH($B$25,'COD Network Fees'!$A$27:$A$29,0)) -> 9.2 | C35: Edit on the fees tab
A36: Cost per lead in market currency | B36: =IF($B$11="USD",$B$10*$B$35,$B$10) -> 18.4
A38: 4. ORDER FUNNEL
A39: Leads | B39: =B12 -> 1000
A40: Confirmed (shipped) orders | B40: =B39*B13 -> 600
A41: Delivered orders | B41: =B40*(1-B14) -> 390 | C41: ="= "&TEXT(B41*$H$10,"#,##0")&" units delivered (incl. free units)" -> = 663 units delivered (incl. free units)
...

Sheet Compare Products
A1: Compare products / markets side by side
A2: One product per row. Offer units (1 / 1+1 free / 2+1 free) and the payment processing fee come from the Calculator. Upsells, overweight surcharge and fixed costs are not included here - use the Calculator for those.
A3: YELLOW = type here | B3: RED = costs | C3: GREEN = profit | D3: BLUE = break-even
A4: Product | B4: Market | C4: Category | D4: Call center? | E4: Price: Buy 1 | F4: Price: Buy 1 Get 1 Free | G4: Price: Buy 2 Get 1 Free | H4: Delivery fee: Buy 1 | I4: Delivery fee: Buy 1 Get 1 Free | J4: Delivery fee: Buy 2 Get 1 Free | K4: % Buy 1 | L4: % Buy 1 Get 1 Free | M4: % Buy 2 Get 1 Free | N4: Product cost per unit | O4: Cost per lead | P4: CPL currency | Q4: Leads | R4: Confirmation rate | S4: Return rate | T4: Currency | U4: Avg order value (incl. delivery fee) | V4: Avg units per order | W4: Confirmed | X4: Delivered | Y4: Revenue | Z4: Ad spend | AA4: Product cost total | AB4: Call center fees | AC4: Shipping | AD4: Fulfillment | AE4: COD fee | AF4: Payment fee | AG4: NET PROFIT | AH4: Profit / delivered | AI4: Margin | AJ4: ROI | AK4: Break-even CPL | AL4: Profit / unit delivered | AM4: Fee row
A5: Example: posture corrector | B5: Morocco | C5: Gadget | D5: Yes | E5: 249 | F5: 349 | G5: 449 | H5: 30 | I5: 0 | J5: 0 | K5: 0.5 | L5: 0.3 | M5: 0.2 | N5: 40 | O5: 2 | P5: USD | Q5: 1000 | R5: 0.6 | S5: 0.35 | T5: =IF($AM5="","",INDEX('COD Network Fees'!$C$5:$C$23,$AM5)) -> MAD | U5: =IF($AM5="","",IF(($K5+$L5+$M5)=0,0,(($E5+$H5)*$K5+($F5+$I5)*$L5+($G5+$J5)*$M5)/($K5+$L5+$M5))) -> 334 | V5: =IF($AM5="","",IF(($K5+$L5+$M5)=0,0,(Calculator!$H$7*$K5+Calculator!$H$8*$L5+Calculator!$H$9*$M5)/($K5+$L5+$M5))) -> 1.7 | W5: =IF($AM5="","",$Q5*$R5) -> 600 | X5: =IF($AM5="","",$W5*(1-$S5)) -> 390 | Y5: =IF($AM5="","",$X5*$U5) -> 130260 | Z5: =IF($AM5="","",$Q5*$O5*IF($P5="USD",INDEX('COD Network Fees'!$B$27:$B$29,MATCH($T5,'COD Network Fees'!$A$27:$A$29,0)),1)) -> 18400 | AA5: =IF($AM5="","",$X5*$V5*$N5) -> 26520 | AB5: =IF($AM5="","",IF($D5="Yes",1,0)*($Q5*IF($C5="Cosmetic",INDEX('COD Network Fees'!$G$5:$G$23,$AM5),INDEX('COD Network Fees'!$D$5:$D$23,$AM5))+$W5*IF($C5="Cosmetic",INDEX('COD Network Fees'!$H$5:$H$23,$AM5),INDEX('COD Network Fees'!$E$5:$E$23,$AM5))+$X5*IF($C5="Cosmetic",INDEX('COD Network Fees'!$I$5:$I$23,$AM5),INDEX('COD Network Fees'!$F$5:$F$23,$AM5)))) -> 7130 | AC5: =IF($AM5="","",$X5*IF(AND($D5="No",INDEX('COD Network Fees'!$M$5:$M$23,$AM5)<>""),INDEX('COD Network Fees'!$M$5:$M$23,$AM5),INDEX('COD Network Fees'!$K$5:$K$23,$AM5))+($W5-$X5)*IF(AND($D5="No",INDEX('COD Network Fees'!$M$5:$M$23,$AM5)<>""),INDEX('COD Network Fees'!$M$5:$M$23,$AM5),INDEX('COD Network Fees'!$L$5:$L$23,$AM5))) -> 15540 | AD5: =IF($AM5="","",$W5*INDEX('COD Network Fees'!$N$5:$N$23,$AM5)) -> 4800 | AE5: =IF($AM5="","",$Y5*INDEX('COD Network Fees'!$P$5:$P$23,$AM5)) -> 0 | AF5: =IF($AM5="","",($Y5-$AB5-$AC5-$AD5-$AE5)*Calculator!$B$19) -> 2055.8 | AG5: =IF($AM5="","",$Y5-$Z5-$AA5-$AB5-$AC5-$AD5-$AE5-$AF5) -> 55814.2 | AH5: =IF($AM5="","",IF($X5=0,0,$AG5/$X5)) -> 143.11333 | AI5: =IF($AM5="","",IF($Y5=0,0,$AG5/$Y5)) -> 0.42848303 | AJ5: =IF($AM5="","",IF(($Z5+$AA5)=0,0,$AG5/($Z5+$AA5))) -> 1.2425245 | AK5: =IF($AM5="","",IF($Q5=0,0,($AG5+$Z5)/$Q5/IF($P5="USD",INDEX('COD Network Fees'!$B$27:$B$29,MATCH($T5,'COD Network Fees'!$A$27:$A$29,0)),1))) -> 8.0667609 | AL5: =IF($AM5="","",IF($X5*$V5=0,0,$AG5/($X5*$V5))) -> 84.184314 | AM5: =IF($B5="","",MATCH($B5,'COD Network Fees'!$A$5:$A$23,0)) -> 7
A6: Example: serum | B6: KSA | C6: Cosmetic | D6: Yes | E6: 39 | F6: 59 | G6: 79 | H6: 0 | I6: 0 | J6: 0 | K6: 0.6 | L6: 0.25 | M6: 0.15 | N6: 6 | O6: 3 | P6: USD | Q6: 500 | R6: 0.55 | S6: 0.3 | T6: =IF($AM6="","",INDEX('COD Network Fees'!$C$5:$C$23,$AM6)) -> USD | U6: =IF($AM6="","",IF(($K6+$L6+$M6)=0,0,(($E6+$H6)*$K6+($F6+$I6)*$L6+($G6+$J6)*$M6)/($K6+$L6+$M6))) -> 50 | V6: =IF($AM6="","",IF(($K6+$L6+$M6)=0,0,(Calculator!$H$7*$K6+Calculator!$H$8*$L6+Calculator!$H$9*$M6)/($K6+$L6+$M6))) -> 1.55 | W6: =IF($AM6="","",$Q6*$R6) -> 275 | X6: =IF($AM6="","",$W6*(1-$S6)) -> 192.5 | Y6: =IF($AM6="","",$X6*$U6) -> 9625 | Z6: =IF($AM6="","",$Q6*$O6*IF($P6="USD",INDEX('COD Network Fees'!$B$27:$B$29,MATCH($T6,'COD Network Fees'!$A$27:$A$29,0)),1)) -> 1500 | AA6: =IF($AM6="","",$X6*$V6*$N6) -> 1790.25 | AB6: =IF($AM6="","",IF($D6="Yes",1,0)*($Q6*IF($C6="Cosmetic",INDEX('COD Network Fees'!$G$5:$G$23,$AM6),INDEX('COD Network Fees'!$D$5:$D$23,$AM6))+$W6*IF($C6="Cosmetic",INDEX('COD Network Fees'!$H$5:$H$23,$AM6),INDEX('COD Network Fees'!$E$5:$E$23,$AM6))+$X6*IF($C6="Cosmetic",INDEX('COD Network Fees'!$I$5:$I$23,$AM6),INDEX('COD Network Fees'!$F$5:$F$23,$AM6)))) -> 1377.5 | AC6: =IF($AM6="","",$X6*IF(AND($D6="No",INDEX('COD Network Fees'!$M$5:$M$23,$AM6)<>""),INDEX('COD Network Fees'!$M$5:$M$23,$AM6),INDEX('COD Network Fees'!$K$5:$K$23,$AM6))+($W6-$X6)*IF(AND($D6="No",INDEX('COD Network Fees'!$M$5:$M$23,$AM6)<>""),INDEX('COD Network Fees'!$M$5:$M$23,$AM6),INDEX('COD Network Fees'!$L$5:$L$23,$AM6))) -> 1207.25 | AD6: =IF($AM6="","",$W6*INDEX('COD Network Fees'!$N$5:$N$23,$AM6)) -> 0 | AE6: =IF($AM6="","",$Y6*INDEX('COD Network Fees'!$P$5:$P$23,$AM6)) -> 481.25 | AF6: =IF($AM6="","",($Y6-$AB6-$AC6-$AD6-$AE6)*Calculator!$B$19) -> 131.18 | AG6: =IF($AM6="","",$Y6-$Z6-$AA6-$AB6-$AC6-$AD6-$AE6-$AF6) -> 3137.57 | AH6: =IF($AM6="","",IF($X6=0,0,$AG6/$X6)) -> 16.299065 | AI6: =IF($AM6="","",IF($Y6=0,0,$AG6/$Y6)) -> 0.3259813 | AJ6: =IF($AM6="","",IF(($Z6+$AA6)=0,0,$AG6/($Z6+$AA6))) -> 0.95359623 | AK6: =IF($AM6="","",IF($Q6=0,0,($AG6+$Z6)/$Q6/IF($P6="USD",INDEX('COD Network Fees'!$B$27:$B$29,MATCH($T6,'COD Network Fees'!$A$27:$A$29,0)),1))) -> 9.27514 | AL6: =IF($AM6="","",IF($X6*$V6=0,0,$AG6/($X6*$V6))) -> 10.515526 | AM6: =IF($B6="","",MATCH($B6,'COD Network Fees'!$A$5:$A$23,0)) -> 2
A7: Example: gummies | B7: Spain | C7: Cosmetic | D7: Yes | E7: 34.9 | F7: 49.9 | G7: 64.9 | H7: 4.99 | I7: 0 | J7: 0 | K7: 0.5 | L7: 0.3 | M7: 0.2 | N7: 5 | O7: 2.5 | P7: Market currency | Q7: 500 | R7: 0.65 | S7: 0.25 | T7: =IF($AM7="","",INDEX('COD Network Fees'!$C$5:$C$23,$AM7)) -> EUR | U7: =IF($AM7="","",IF(($K7+$L7+$M7)=0,0,(($E7+$H7)*$K7+($F7+$I7)*$L7+($G7+$J7)*$M7)/($K7+$L7+$M7))) -> 47.895 | V7: =IF($AM7="","",IF(($K7+$L7+$M7)=0,0,(Calculator!$H$7*$K7+Calculator!$H$8*$L7+Calculator!$H$9*$M7)/($K7+$L7+$M7))) -> 1.7 | W7: =IF($AM7="","",$Q7*$R7) -> 325 | X7: =IF($AM7="","",$W7*(1-$S7)) -> 243.75 | Y7: =IF($AM7="","",$X7*$U7) -> 11674.406 | Z7: =IF($AM7="","",$Q7*$O7*IF($P7="USD",INDEX('COD Network Fees'!$B$27:$B$29,MATCH($T7,'COD Network Fees'!$A$27:$A$29,0)),1)) -> 1250 | AA7: =IF($AM7="","",$X7*$V7*$N7) -> 2071.875 | AB7: =IF($AM7="","",IF($D7="Yes",1,0)*($Q7*IF($C7="Cosmetic",INDEX('COD Network Fees'!$G$5:$G$23,$AM7),INDEX('COD Network Fees'!$D$5:$D$23,$AM7))+$W7*IF($C7="Cosmetic",INDEX('COD Network Fees'!$H$5:$H$23,$AM7),INDEX('COD Network Fees'!$E$5:$E$23,$AM7))+$X7*IF($C7="Cosmetic",INDEX('COD Network Fees'!$I$5:$I$23,$AM7),INDEX('COD Network Fees'!$F$5:$F$23,$AM7)))) -> 1062.5 | AC7: =IF($AM7="","",$X7*IF(AND($D7="No",INDEX('COD Network Fees'!$M$5:$M$23,$AM7)<>""),INDEX('COD Network Fees'!$M$5:$M$23,$AM7),INDEX('COD Network Fees'!$K$5:$K$23,$AM7))+($W7-$X7)*IF(AND($D7="No",INDEX('COD Network Fees'!$M$5:$M$23,$AM7)<>""),INDEX('COD Network Fees'!$M$5:$M$23,$AM7),INDEX('COD Network Fees'!$L$5:$L$23,$AM7))) -> 2515.5 | AD7: =IF($AM7="","",$W7*INDEX('COD Network Fees'!$N$5:$N$23,$AM7)) -> 0 | AE7: =IF($AM7="","",$Y7*INDEX('COD Network Fees'!$P$5:$P$23,$AM7)) -> 583.72031 | AF7: =IF($AM7="","",($Y7-$AB7-$AC7-$AD7-$AE7)*Calculator!$B$19) -> 150.25372 | AG7: =IF($AM7="","",$Y7-$Z7-$AA7-$AB7-$AC7-$AD7-$AE7-$AF7) -> 4040.5572 | AH7: =IF($AM7="","",IF($X7=0,0,$AG7/$X7)) -> 16.576645 | AI7: =IF($AM7="","",IF($Y7=0,0,$AG7/$Y7)) -> 0.34610387 | AJ7: =IF($AM7="","",IF(($Z7+$AA7)=0,0,$AG7/($Z7+$AA7))) -> 1.2163484 | AK7: =IF($AM7="","",IF($Q7=0,0,($AG7+$Z7)/$Q7/IF($P7="USD",INDEX('COD Network Fees'!$B$27:$B$29,MATCH($T7,'COD Network Fees'!$A$27:$A$29,0)),1))) -> 10.581114 | AL7: =IF($AM7="","",IF($X7*$V7=0,0,$AG7/($X7*$V7))) -> 9.7509676 | AM7: =IF($B7="","",MATCH($B7,'COD Network Fees'!$A$5:$A$23,0)) -> 8
T8: =IF($AM8="","",INDEX('COD Network Fees'!$C$5:$C$23,$AM8)) | U8: =IF($AM8="","",IF(($K8+$L8+$M8)=0,0,(($E8+$H8)*$K8+($F8+$I8)*$L8+($G8+$J8)*$M8)/($K8+$L8+$M8))) | V8: =IF($AM8="","",IF(($K8+$L8+$M8)=0,0,(Calculator!$H$7*$K8+Calculator!$H$8*$L8+Calculator!$H$9*$M8)/($K8+$L8+$M8))) | W8: =IF($AM8="","",$Q8*$R8) | X8: =IF($AM8="","",$W8*(1-$S8)) | Y8: =IF($AM8="","",$X8*$U8) | Z8: =IF($AM8="","",$Q8*$O8*IF($P8="USD",INDEX('COD Network Fees'!$B$27:$B$29,MATCH($T8,'COD Network Fees'!$A$27:$A$29,0)),1)) | AA8: =IF($AM8="","",$X8*$V8*$N8) | AB8: =IF($AM8="","",IF($D8="Yes",1,0)*($Q8*IF($C8="Cosmetic",INDEX('COD Network Fees'!$G$5:$G$23,$AM8),INDEX('COD Network Fees'!$D$5:$D$23,$AM8))+$W8*IF($C8="Cosmetic",INDEX('COD Network Fees'!$H$5:$H$23,$AM8),INDEX('COD Network Fees'!$E$5:$E$23,$AM8))+$X8*IF($C8="Cosmetic",INDEX('COD Network Fees'!$I$5:$I$23,$AM8),INDEX('COD Network Fees'!$F$5:$F$23,$AM8)))) | AC8: =IF($AM8="","",$X8*IF(AND($D8="No",INDEX('COD Network Fees'!$M$5:$M$23,$AM8)<>""),INDEX('COD Network Fees'!$M$5:$M$23,$AM8),INDEX('COD Network Fees'!$K$5:$K$23,$AM8))+($W8-$X8)*IF(AND($D8="No",INDEX('COD Network Fees'!$M$5:$M$23,$AM8)<>""),INDEX('COD Network Fees'!$M$5:$M$23,$AM8),INDEX('COD Network Fees'!$L$5:$L$23,$AM8))) | AD8: =IF($AM8="","",$W8*INDEX('COD Network Fees'!$N$5:$N$23,$AM8)) | AE8: =IF($AM8="","",$Y8*INDEX('COD Network Fees'!$P$5:$P$23,$AM8)) | AF8: =IF($AM8="","",($Y8-$AB8-$AC8-$AD8-$AE8)*Calculator!$B$19) | AG8: =IF($AM8="","",$Y8-$Z8-$AA8-$AB8-$AC8-$AD8-$AE8-$AF8) | AH8: =IF($AM8="","",IF($X8=0,0,$AG8/$X8)) | AI8: =IF($AM8="","",IF($Y8=0,0,$AG8/$Y8)) | AJ8: =IF($AM8="","",IF(($Z8+$AA8)=0,0,$AG8/($Z8+$AA8))) | AK8: =IF($AM8="","",IF($Q8=0,0,($AG8+$Z8)/$Q8/IF($P8="USD",INDEX('COD Network Fees'!$B$27:$B$29,MATCH($T8,'COD Network Fees'!$A$27:$A$29,0)),1))) | AL8: =IF($AM8="","",IF($X8*$V8=0,0,$AG8/($X8*$V8))) | AM8: =IF($B8="","",MATCH($B8,'COD Network Fees'!$A$5:$A$23,0))
T9: =IF($AM9="","",INDEX('COD Network Fees'!$C$5:$C$23,$AM9)) | U9: =IF($AM9="","",IF(($K9+$L9+$M9)=0,0,(($E9+$H9)*$K9+($F9+$I9)*$L9+($G9+$J9)*$M9)/($K9+$L9+$M9))) | V9: =IF($AM9="","",IF(($K9+$L9+$M9)=0,0,(Calculator!$H$7*$K9+Calculator!$H$8*$L9+Calculator!$H$9*$M9)/($K9+$L9+$M9))) | W9: =IF($AM9="","",$Q9*$R9) | X9: =IF($AM9="","",$W9*(1-$S9)) | Y9: =IF($AM9="","",$X9*$U9) | Z9: =IF($AM9="","",$Q9*$O9*IF($P9="USD",INDEX('COD Network Fees'!$B$27:$B$29,MATCH($T9,'COD Network Fees'!$A$27:$A$29,0)),1)) | AA9: =IF($AM9="","",$X9*$V9*$N9) | AB9: =IF($AM9="","",IF($D9="Yes",1,0)*($Q9*IF($C9="Cosmetic",INDEX('COD Network Fees'!$G$5:$G$23,$AM9),INDEX('COD Network Fees'!$D$5:$D$23,$AM9))+$W9*IF($C9="Cosmetic",INDEX('COD Network Fees'!$H$5:$H$23,$AM9),INDEX('COD Network Fees'!$E$5:$E$23,$AM9))+$X9*IF($C9="Cosmetic",INDEX('COD Network Fees'!$I$5:$I$23,$AM9),INDEX('COD Network Fees'!$F$5:$F$23,$AM9)))) | AC9: =IF($AM9="","",$X9*IF(AND($D9="No",INDEX('COD Network Fees'!$M$5:$M$23,$AM9)<>""),INDEX('COD Network Fees'!$M$5:$M$23,$AM9),INDEX('COD Network Fees'!$K$5:$K$23,$AM9))+($W9-$X9)*IF(AND($D9="No",INDEX('COD Network Fees'!$M$5:$M$23,$AM9)<>""),INDEX('COD Network Fees'!$M$5:$M$23,$AM9),INDEX('COD Network Fees'!$L$5:$L$23,$AM9))) | AD9: =IF($AM9="","",$W9*INDEX('COD Network Fees'!$N$5:$N$23,$AM9)) | AE9: =IF($AM9="","",$Y9*INDEX('COD Network Fees'!$P$5:$P$23,$AM9)) | AF9: =IF($AM9="","",($Y9-$AB9-$AC9-$AD9-$AE9)*Calculator!$B$19) | AG9: =IF($AM9="","",$Y9-$Z9-$AA9-$AB9-$AC9-$AD9-$AE9-$AF9) | AH9: =IF($AM9="","",IF($X9=0,0,$AG9/$X9)) | AI9: =IF($AM9="","",IF($Y9=0,0,$AG9/$Y9)) | AJ9: =IF($AM9="","",IF(($Z9+$AA9)=0,0,$AG9/($Z9+$AA9))) | AK9: =IF($AM9="","",IF($Q9=0,0,($AG9+$Z9)/$Q9/IF($P9="USD",INDEX('COD Network Fees'!$B$27:$B$29,MATCH($T9,'COD Network Fees'!$A$27:$A$29,0)),1))) | AL9: =IF($AM9="","",IF($X9*$V9=0,0,$AG9/($X9*$V9))) | AM9: =IF($B9="","",MATCH($B9,'COD Network Fees'!$A$5:$A$23,0))
T10: =IF($AM10="","",INDEX('COD Network Fees'!$C$5:$C$23,$AM10)) | U10: =IF($AM10="","",IF(($K10+$L10+$M10)=0,0,(($E10+$H10)*$K10+($F10+$I10)*$L10+($G10+$J10)*$M10)/($K10+$L10+$M10))) | V10: =IF($AM10="","",IF(($K10+$L10+$M10)=0,0,(Calculator!$H$7*$K10+Calculator!$H$8*$L10+Calculator!$H$9*$M10)/($K10+$L10+$M10))) | W10: =IF($AM10="","",$Q10*$R10) | X10: =IF($AM10="","",$W10*(1-$S10)) | Y10: =IF($AM10="","",$X10*$U10) | Z10: =IF($AM10="","",$Q10*$O10*IF($P10="USD",INDEX('COD Network Fees'!$B$27:$B$29,MATCH($T10,'COD Network Fees'!$A$27:$A$29,0)),1)) | AA10: =IF($AM10="","",$X10*$V10*$N10) | AB10: =IF($AM10="","",IF($D10="Yes",1,0)*($Q10*IF($C10="Cosmetic",INDEX('COD Network Fees'!$G$5:$G$23,$AM10),INDEX('COD Network Fees'!$D$5:$D$23,$AM10))+$W10*IF($C10="Cosmetic",INDEX('COD Network Fees'!$H$5:$H$23,$AM10),INDEX('COD Network Fees'!$E$5:$E$23,$AM10))+$X10*IF($C10="Cosmetic",INDEX('COD Network Fees'!$I$5:$I$23,$AM10),INDEX('COD Network Fees'!$F$5:$F$23,$AM10)))) | AC10: =IF($AM10="","",$X10*IF(AND($D10="No",INDEX('COD Network Fees'!$M$5:$M$23,$AM10)<>""),INDEX('COD Network Fees'!$M$5:$M$23,$AM10),INDEX('COD Network Fees'!$K$5:$K$23,$AM10))+($W10-$X10)*IF(AND($D10="No",INDEX('COD Network Fees'!$M$5:$M$23,$AM10)<>""),INDEX('COD Network Fees'!$M$5:$M$23,$AM10),INDEX('COD Network Fees'!$L$5:$L$23,$AM10))) | AD10: =IF($AM10="","",$W10*INDEX('COD Network Fees'!$N$5:$N$23,$AM10)) | AE10: =IF($AM10="","",$Y10*INDEX('COD Network Fees'!$P$5:$P$23,$AM10)) | AF10: =IF($AM10="","",($Y10-$AB10-$AC10-$AD10-$AE10)*Calculator!$B$19) | AG10: =IF($AM10="","",$Y10-$Z10-$AA10-$AB10-$AC10-$AD10-$AE10-$AF10) | AH10: =IF($AM10="","",IF($X10=0,0,$AG10/$X10)) | AI10: =IF($AM10="","",IF($Y10=0,0,$AG10/$Y10)) | AJ10: =IF($AM10="","",IF(($Z10+$AA10)=0,0,$AG10/($Z10+$AA10))) | AK10: =IF($AM10="","",IF($Q10=0,0,($AG10+$Z10)/$Q10/IF($P10="USD",INDEX('COD Network Fees'!$B$27:$B$29,MATCH($T10,'COD Network Fees'!$A$27:$A$29,0)),1))) | AL10: =IF($AM10="","",IF($X10*$V10=0,0,$AG10/($X10*$V10))) | AM10: =IF($B10="","",MATCH($B10,'COD Network Fees'!$A$5:$A$23,0))
T11: =IF($AM11="","",INDEX('COD Network Fees'!$C$5:$C$23,$AM11)) | U11: =IF($AM11="","",IF(($K11+$L11+$M11)=0,0,(($E11+$H11)*$K11+($F11+$I11)*$L11+($G11+$J11)*$M11)/($K11+$L11+$M11))) | V11: =IF($AM11="","",IF(($K11+$L11+$M11)=0,0,(Calculator!$H$7*$K11+Calculator!$H$8*$L11+Calculator!$H$9*$M11)/($K11+$L11+$M11))) | W11: =IF($AM11="","",$Q11*$R11) | X11: =IF($AM11="","",$W11*(1-$S11)) | Y11: =IF($AM11="","",$X11*$U11) | Z11: =IF($AM11="","",$Q11*$O11*IF($P11="USD",INDEX('COD Network Fees'!$B$27:$B$29,MATCH($T11,'COD Network Fees'!$A$27:$A$29,0)),1)) | AA11: =IF($AM11="","",$X11*$V11*$N11) | AB11: =IF($AM11="","",IF($D11="Yes",1,0)*($Q11*IF($C11="Cosmetic",INDEX('COD Network Fees'!$G$5:$G$23,$AM11),INDEX('COD Network Fees'!$D$5:$D$23,$AM11))+$W11*IF($C11="Cosmetic",INDEX('COD Network Fees'!$H$5:$H$23,$AM11),INDEX('COD Network Fees'!$E$5:$E$23,$AM11))+$X11*IF($C11="Cosmetic",INDEX('COD Network Fees'!$I$5:$I$23,$AM11),INDEX('COD Network Fees'!$F$5:$F$23,$AM11)))) | AC11: =IF($AM11="","",$X11*IF(AND($D11="No",INDEX('COD Network Fees'!$M$5:$M$23,$AM11)<>""),INDEX('COD Network Fees'!$M$5:$M$23,$AM11),INDEX('COD Network Fees'!$K$5:$K$23,$AM11))+($W11-$X11)*IF(AND($D11="No",INDEX('COD Network Fees'!$M$5:$M$23,$AM11)<>""),INDEX('COD Network Fees'!$M$5:$M$23,$AM11),INDEX('COD Network Fees'!$L$5:$L$23,$AM11))) | AD11: =IF($AM11="","",$W11*INDEX('COD Network Fees'!$N$5:$N$23,$AM11)) | AE11: =IF($AM11="","",$Y11*INDEX('COD Network Fees'!$P$5:$P$23,$AM11)) | AF11: =IF($AM11="","",($Y11-$AB11-$AC11-$AD11-$AE11)*Calculator!$B$19) | AG11: =IF($AM11="","",$Y11-$Z11-$AA11-$AB11-$AC11-$AD11-$AE11-$AF11) | AH11: =IF($AM11="","",IF($X11=0,0,$AG11/$X11)) | AI11: =IF($AM11="","",IF($Y11=0,0,$AG11/$Y11)) | AJ11: =IF($AM11="","",IF(($Z11+$AA11)=0,0,$AG11/($Z11+$AA11))) | AK11: =IF($AM11="","",IF($Q11=0,0,($AG11+$Z11)/$Q11/IF($P11="USD",INDEX('COD Network Fees'!$B$27:$B$29,MATCH($T11,'COD Network Fees'!$A$27:$A$29,0)),1))) | AL11: =IF($AM11="","",IF($X11*$V11=0,0,$AG11/($X11*$V11))) | AM11: =IF($B11="","",MATCH($B11,'COD Network Fees'!$A$5:$A$23,0))
T12: =IF($AM12="","",INDEX('COD Network Fees'!$C$5:$C$23,$AM12)) | U12: =IF($AM12="","",IF(($K12+$L12+$M12)=0,0,(($E12+$H12)*$K12+($F12+$I12)*$L12+($G12+$J12)*$M12)/($K12+$L12+$M12))) | V12: =IF($AM12="","",IF(($K12+$L12+$M12)=0,0,(Calculator!$H$7*$K12+Calculator!$H$8*$L12+Calculator!$H$9*$M12)/($K12+$L12+$M12))) | W12: =IF($AM12="","",$Q12*$R12) | X12: =IF($AM12="","",$W12*(1-$S12)) | Y12: =IF($AM12="","",$X12*$U12) | Z12: =IF($AM12="","",$Q12*$O12*IF($P12="USD",INDEX('COD Network Fees'!$B$27:$B$29,MATCH($T12,'COD Network Fees'!$A$27:$A$29,0)),1)) | AA12: =IF($AM12="","",$X12*$V12*$N12) | AB12: =IF($AM12="","",IF($D12="Yes",1,0)*($Q12*IF($C12="Cosmetic",INDEX('COD Network Fees'!$G$5:$G$23,$AM12),INDEX('COD Network Fees'!$D$5:$D$23,$AM12))+$W12*IF($C12="Cosmetic",INDEX('COD Network Fees'!$H$5:$H$23,$AM12),INDEX('COD Network Fees'!$E$5:$E$23,$AM12))+$X12*IF($C12="Cosmetic",INDEX('COD Network Fees'!$I$5:$I$23,$AM12),INDEX('COD Network Fees'!$F$5:$F$23,$AM12)))) | AC12: =IF($AM12="","",$X12*IF(AND($D12="No",INDEX('COD Network Fees'!$M$5:$M$23,$AM12)<>""),INDEX('COD Network Fees'!$M$5:$M$23,$AM12),INDEX('COD Network Fees'!$K$5:$K$23,$AM12))+($W12-$X12)*IF(AND($D12="No",INDEX('COD Network Fees'!$M$5:$M$23,$AM12)<>""),INDEX('COD Network Fees'!$M$5:$M$23,$AM12),INDEX('COD Network Fees'!$L$5:$L$23,$AM12))) | AD12: =IF($AM12="","",$W12*INDEX('COD Network Fees'!$N$5:$N$23,$AM12)) | AE12: =IF($AM12="","",$Y12*INDEX('COD Network Fees'!$P$5:$P$23,$AM12)) | AF12: =IF($AM12="","",($Y12-$AB12-$AC12-$AD12-$AE12)*Calculator!$B$19) | AG12: =IF($AM12="","",$Y12-$Z12-$AA12-$AB12-$AC12-$AD12-$AE12-$AF12) | AH12: =IF($AM12="","",IF($X12=0,0,$AG12/$X12)) | AI12: =IF($AM12="","",IF($Y12=0,0,$AG12/$Y12)) | AJ12: =IF($AM12="","",IF(($Z12+$AA12)=0,0,$AG12/($Z12+$AA12))) | AK12: =IF($AM12="","",IF($Q12=0,0,($AG12+$Z12)/$Q12/IF($P12="USD",INDEX('COD Network Fees'!$B$27:$B$29,MATCH($T12,'COD Network Fees'!$A$27:$A$29,0)),1))) | AL12: =IF($AM12="","",IF($X12*$V12=0,0,$AG12/($X12*$V12))) | AM12: =IF($B12="","",MATCH($B12,'COD Network Fees'!$A$5:$A$23,0))
T13: =IF($AM13="","",INDEX('COD Network Fees'!$C$5:$C$23,$AM13)) | U13: =IF($AM13="","",IF(($K13+$L13+$M13)=0,0,(($E13+$H13)*$K13+($F13+$I13)*$L13+($G13+$J13)*$M13)/($K13+$L13+$M13))) | V13: =IF($AM13="","",IF(($K13+$L13+$M13)=0,0,(Calculator!$H$7*$K13+Calculator!$H$8*$L13+Calculator!$H$9*$M13)/($K13+$L13+$M13))) | W13: =IF($AM13="","",$Q13*$R13) | X13: =IF($AM13="","",$W13*(1-$S13)) | Y13: =IF($AM13="","",$X13*$U13) | Z13: =IF($AM13="","",$Q13*$O13*IF($P13="USD",INDEX('COD Network Fees'!$B$27:$B$29,MATCH($T13,'COD Network Fees'!$A$27:$A$29,0)),1)) | AA13: =IF($AM13="","",$X13*$V13*$N13) | AB13: =IF($AM13="","",IF($D13="Yes",1,0)*($Q13*IF($C13="Cosmetic",INDEX('COD Network Fees'!$G$5:$G$23,$AM13),INDEX('COD Network Fees'!$D$5:$D$23,$AM13))+$W13*IF($C13="Cosmetic",INDEX('COD Network Fees'!$H$5:$H$23,$AM13),INDEX('COD Network Fees'!$E$5:$E$23,$AM13))+$X13*IF($C13="Cosmetic",INDEX('COD Network Fees'!$I$5:$I$23,$AM13),INDEX('COD Network Fees'!$F$5:$F$23,$AM13)))) | AC13: =IF($AM13="","",$X13*IF(AND($D13="No",INDEX('COD Network Fees'!$M$5:$M$23,$AM13)<>""),INDEX('COD Network Fees'!$M$5:$M$23,$AM13),INDEX('COD Network Fees'!$K$5:$K$23,$AM13))+($W13-$X13)*IF(AND($D13="No",INDEX('COD Network Fees'!$M$5:$M$23,$AM13)<>""),INDEX('COD Network Fees'!$M$5:$M$23,$AM13),INDEX('COD Network Fees'!$L$5:$L$23,$AM13))) | AD13: =IF($AM13="","",$W13*INDEX('COD Network Fees'!$N$5:$N$23,$AM13)) | AE13: =IF($AM13="","",$Y13*INDEX('COD Network Fees'!$P$5:$P$23,$AM13)) | AF13: =IF($AM13="","",($Y13-$AB13-$AC13-$AD13-$AE13)*Calculator!$B$19) | AG13: =IF($AM13="","",$Y13-$Z13-$AA13-$AB13-$AC13-$AD13-$AE13-$AF13) | AH13: =IF($AM13="","",IF($X13=0,0,$AG13/$X13)) | AI13: =IF($AM13="","",IF($Y13=0,0,$AG13/$Y13)) | AJ13: =IF($AM13="","",IF(($Z13+$AA13)=0,0,$AG13/($Z13+$AA13))) | AK13: =IF($AM13="","",IF($Q13=0,0,($AG13+$Z13)/$Q13/IF($P13="USD",INDEX('COD Network Fees'!$B$27:$B$29,MATCH($T13,'COD Network Fees'!$A$27:$A$29,0)),1))) | AL13: =IF($AM13="","",IF($X13*$V13=0,0,$AG13/($X13*$V13))) | AM13: =IF($B13="","",MATCH($B13,'COD Network Fees'!$A$5:$A$23,0))
T14: =IF($AM14="","",INDEX('COD Network Fees'!$C$5:$C$23,$AM14)) | U14: =IF($AM14="","",IF(($K14+$L14+$M14)=0,0,(($E14+$H14)*$K14+($F14+$I14)*$L14+($G14+$J14)*$M14)/($K14+$L14+$M14))) | V14: =IF($AM14="","",IF(($K14+$L14+$M14)=0,0,(Calculator!$H$7*$K14+Calculator!$H$8*$L14+Calculator!$H$9*$M14)/($K14+$L14+$M14))) | W14: =IF($AM14="","",$Q14*$R14) | X14: =IF($AM14="","",$W14*(1-$S14)) | Y14: =IF($AM14="","",$X14*$U14) | Z14: =IF($AM14="","",$Q14*$O14*IF($P14="USD",INDEX('COD Network Fees'!$B$27:$B$29,MATCH($T14,'COD Network Fees'!$A$27:$A$29,0)),1)) | AA14: =IF($AM14="","",$X14*$V14*$N14) | AB14: =IF($AM14="","",IF($D14="Yes",1,0)*($Q14*IF($C14="Cosmetic",INDEX('COD Network Fees'!$G$5:$G$23,$AM14),INDEX('COD Network Fees'!$D$5:$D$23,$AM14))+$W14*IF($C14="Cosmetic",INDEX('COD Network Fees'!$H$5:$H$23,$AM14),INDEX('COD Network Fees'!$E$5:$E$23,$AM14))+$X14*IF($C14="Cosmetic",INDEX('COD Network Fees'!$I$5:$I$23,$AM14),INDEX('COD Network Fees'!$F$5:$F$23,$AM14)))) | AC14: =IF($AM14="","",$X14*IF(AND($D14="No",INDEX('COD Network Fees'!$M$5:$M$23,$AM14)<>""),INDEX('COD Network Fees'!$M$5:$M$23,$AM14),INDEX('COD Network Fees'!$K$5:$K$23,$AM14))+($W14-$X14)*IF(AND($D14="No",INDEX('COD Network Fees'!$M$5:$M$23,$AM14)<>""),INDEX('COD Network Fees'!$M$5:$M$23,$AM14),INDEX('COD Network Fees'!$L$5:$L$23,$AM14))) | AD14: =IF($AM14="","",$W14*INDEX('COD Network Fees'!$N$5:$N$23,$AM14)) | AE14: =IF($AM14="","",$Y14*INDEX('COD Network Fees'!$P$5:$P$23,$AM14)) | AF14: =IF($AM14="","",($Y14-$AB14-$AC14-$AD14-$AE14)*Calculator!$B$19) | AG14: =IF($AM14="","",$Y14-$Z14-$AA14-$AB14-$AC14-$AD14-$AE14-$AF14) | AH14: =IF($AM14="","",IF($X14=0,0,$AG14/$X14)) | AI14: =IF($AM14="","",IF($Y14=0,0,$AG14/$Y14)) | AJ14: =IF($AM14="","",IF(($Z14+$AA14)=0,0,$AG14/($Z14+$AA14))) | AK14: =IF($AM14="","",IF($Q14=0,0,($AG14+$Z14)/$Q14/IF($P14="USD",INDEX('COD Network Fees'!$B$27:$B$29,MATCH($T14,'COD Network Fees'!$A$27:$A$29,0)),1))) | AL14: =IF($AM14="","",IF($X14*$V14=0,0,$AG14/($X14*$V14))) | AM14: =IF($B14="","",MATCH($B14,'COD Network Fees'!$A$5:$A$23,0))
T15: =IF($AM15="","",INDEX('COD Network Fees'!$C$5:$C$23,$AM15)) | U15: =IF($AM15="","",IF(($K15+$L15+$M15)=0,0,(($E15+$H15)*$K15+($F15+$I15)*$L15+($G15+$J15)*$M15)/($K15+$L15+$M15))) | V15: =IF($AM15="","",IF(($K15+$L15+$M15)=0,0,(Calculator!$H$7*$K15+Calculator!$H$8*$L15+Calculator!$H$9*$M15)/($K15+$L15+$M15))) | W15: =IF($AM15="","",$Q15*$R15) | X15: =IF($AM15="","",$W15*(1-$S15)) | Y15: =IF($AM15="","",$X15*$U15) | Z15: =IF($AM15="","",$Q15*$O15*IF($P15="USD",INDEX('COD Network Fees'!$B$27:$B$29,MATCH($T15,'COD Network Fees'!$A$27:$A$29,0)),1)) | AA15: =IF($AM15="","",$X15*$V15*$N15) | AB15: =IF($AM15="","",IF($D15="Yes",1,0)*($Q15*IF($C15="Cosmetic",INDEX('COD Network Fees'!$G$5:$G$23,$AM15),INDEX('COD Network Fees'!$D$5:$D$23,$AM15))+$W15*IF($C15="Cosmetic",INDEX('COD Network Fees'!$H$5:$H$23,$AM15),INDEX('COD Network Fees'!$E$5:$E$23,$AM15))+$X15*IF($C15="Cosmetic",INDEX('COD Network Fees'!$I$5:$I$23,$AM15),INDEX('COD Network Fees'!$F$5:$F$23,$AM15)))) | AC15: =IF($AM15="","",$X15*IF(AND($D15="No",INDEX('COD Network Fees'!$M$5:$M$23,$AM15)<>""),INDEX('COD Network Fees'!$M$5:$M$23,$AM15),INDEX('COD Network Fees'!$K$5:$K$23,$AM15))+($W15-$X15)*IF(AND($D15="No",INDEX('COD Network Fees'!$M$5:$M$23,$AM15)<>""),INDEX('COD Network Fees'!$M$5:$M$23,$AM15),INDEX('COD Network Fees'!$L$5:$L$23,$AM15))) | AD15: =IF($AM15="","",$W15*INDEX('COD Network Fees'!$N$5:$N$23,$AM15)) | AE15: =IF($AM15="","",$Y15*INDEX('COD Network Fees'!$P$5:$P$23,$AM15)) | AF15: =IF($AM15="","",($Y15-$AB15-$AC15-$AD15-$AE15)*Calculator!$B$19) | AG15: =IF($AM15="","",$Y15-$Z15-$AA15-$AB15-$AC15-$AD15-$AE15-$AF15) | AH15: =IF($AM15="","",IF($X15=0,0,$AG15/$X15)) | AI15: =IF($AM15="","",IF($Y15=0,0,$AG15/$Y15)) | AJ15: =IF($AM15="","",IF(($Z15+$AA15)=0,0,$AG15/($Z15+$AA15))) | AK15: =IF($AM15="","",IF($Q15=0,0,($AG15+$Z15)/$Q15/IF($P15="USD",INDEX('COD Network Fees'!$B$27:$B$29,MATCH($T15,'COD Network Fees'!$A$27:$A$29,0)),1))) | AL15: =IF($AM15="","",IF($X15*$V15=0,0,$AG15/($X15*$V15))) | AM15: =IF($B15="","",MATCH($B15,'COD Network Fees'!$A$5:$A$23,0))
T16: =IF($AM16="","",INDEX('COD Network Fees'!$C$5:$C$23,$AM16)) | U16: =IF($AM16="","",IF(($K16+$L16+$M16)=0,0,(($E16+$H16)*$K16+($F16+$I16)*$L16+($G16+$J16)*$M16)/($K16+$L16+$M16))) | V16: =IF($AM16="","",IF(($K16+$L16+$M16)=0,0,(Calculator!$H$7*$K16+Calculator!$H$8*$L16+Calculator!$H$9*$M16)/($K16+$L16+$M16))) | W16: =IF($AM16="","",$Q16*$R16) | X16: =IF($AM16="","",$W16*(1-$S16)) | Y16: =IF($AM16="","",$X16*$U16) | Z16: =IF($AM16="","",$Q16*$O16*IF($P16="USD",INDEX('COD Network Fees'!$B$27:$B$29,MATCH($T16,'COD Network Fees'!$A$27:$A$29,0)),1)) | AA16: =IF($AM16="","",$X16*$V16*$N16) | AB16: =IF($AM16="","",IF($D16="Yes",1,0)*($Q16*IF($C16="Cosmetic",INDEX('COD Network Fees'!$G$5:$G$23,$AM16),INDEX('COD Network Fees'!$D$5:$D$23,$AM16))+$W16*IF($C16="Cosmetic",INDEX('COD Network Fees'!$H$5:$H$23,$AM16),INDEX('COD Network Fees'!$E$5:$E$23,$AM16))+$X16*IF($C16="Cosmetic",INDEX('COD Network Fees'!$I$5:$I$23,$AM16),INDEX('COD Network Fees'!$F$5:$F$23,$AM16)))) | AC16: =IF($AM16="","",$X16*IF(AND($D16="No",INDEX('COD Network Fees'!$M$5:$M$23,$AM16)<>""),INDEX('COD Network Fees'!$M$5:$M$23,$AM16),INDEX('COD Network Fees'!$K$5:$K$23,$AM16))+($W16-$X16)*IF(AND($D16="No",INDEX('COD Network Fees'!$M$5:$M$23,$AM16)<>""),INDEX('COD Network Fees'!$M$5:$M$23,$AM16),INDEX('COD Network Fees'!$L$5:$L$23,$AM16))) | AD16: =IF($AM16="","",$W16*INDEX('COD Network Fees'!$N$5:$N$23,$AM16)) | AE16: =IF($AM16="","",$Y16*INDEX('COD Network Fees'!$P$5:$P$23,$AM16)) | AF16: =IF($AM16="","",($Y16-$AB16-$AC16-$AD16-$AE16)*Calculator!$B$19) | AG16: =IF($AM16="","",$Y16-$Z16-$AA16-$AB16-$AC16-$AD16-$AE16-$AF16) | AH16: =IF($AM16="","",IF($X16=0,0,$AG16/$X16)) | AI16: =IF($AM16="","",IF($Y16=0,0,$AG16/$Y16)) | AJ16: =IF($AM16="","",IF(($Z16+$AA16)=0,0,$AG16/($Z16+$AA16))) | AK16: =IF($AM16="","",IF($Q16=0,0,($AG16+$Z16)/$Q16/IF($P16="USD",INDEX('COD Network Fees'!$B$27:$B$29,MATCH($T16,'COD Network Fees'!$A$27:$A$29,0)),1))) | AL16: =IF($AM16="","",IF($X16*$V16=0,0,$AG16/($X16*$V16))) | AM16: =IF($B16="","",MATCH($B16,'COD Network Fees'!$A$5:$A$23,0))
T17: =IF($AM17="","",INDEX('COD Network Fees'!$C$5:$C$23,$AM17)) | U17: =IF($AM17="","",IF(($K17+$L17+$M17)=0,0,(($E17+$H17)*$K17+($F17+$I17)*$L17+($G17+$J17)*$M17)/($K17+$L17+$M17))) | V17: =IF($AM17="","",IF(($K17+$L17+$M17)=0,0,(Calculator!$H$7*$K17+Calculator!$H$8*$L17+Calculator!$H$9*$M17)/($K17+$L17+$M17))) | W17: =IF($AM17="","",$Q17*$R17) | X17: =IF($AM17="","",$W17*(1-$S17)) | Y17: =IF($AM17="","",$X17*$U17) | Z17: =IF($AM17="","",$Q17*$O17*IF($P17="USD",INDEX('COD Network Fees'!$B$27:$B$29,MATCH($T17,'COD Network Fees'!$A$27:$A$29,0)),1)) | AA17: =IF($AM17="","",$X17*$V17*$N17) | AB17: =IF($AM17="","",IF($D17="Yes",1,0)*($Q17*IF($C17="Cosmetic",INDEX('COD Network Fees'!$G$5:$G$23,$AM17),INDEX('COD Network Fees'!$D$5:$D$23,$AM17))+$W17*IF($C17="Cosmetic",INDEX('COD Network Fees'!$H$5:$H$23,$AM17),INDEX('COD Network Fees'!$E$5:$E$23,$AM17))+$X17*IF($C17="Cosmetic",INDEX('COD Network Fees'!$I$5:$I$23,$AM17),INDEX('COD Network Fees'!$F$5:$F$23,$AM17)))) | AC17: =IF($AM17="","",$X17*IF(AND($D17="No",INDEX('COD Network Fees'!$M$5:$M$23,$AM17)<>""),INDEX('COD Network Fees'!$M$5:$M$23,$AM17),INDEX('COD Network Fees'!$K$5:$K$23,$AM17))+($W17-$X17)*IF(AND($D17="No",INDEX('COD Network Fees'!$M$5:$M$23,$AM17)<>""),INDEX('COD Network Fees'!$M$5:$M$23,$AM17),INDEX('COD Network Fees'!$L$5:$L$23,$AM17))) | AD17: =IF($AM17="","",$W17*INDEX('COD Network Fees'!$N$5:$N$23,$AM17)) | AE17: =IF($AM17="","",$Y17*INDEX('COD Network Fees'!$P$5:$P$23,$AM17)) | AF17: =IF($AM17="","",($Y17-$AB17-$AC17-$AD17-$AE17)*Calculator!$B$19) | AG17: =IF($AM17="","",$Y17-$Z17-$AA17-$AB17-$AC17-$AD17-$AE17-$AF17) | AH17: =IF($AM17="","",IF($X17=0,0,$AG17/$X17)) | AI17: =IF($AM17="","",IF($Y17=0,0,$AG17/$Y17)) | AJ17: =IF($AM17="","",IF(($Z17+$AA17)=0,0,$AG17/($Z17+$AA17))) | AK17: =IF($AM17="","",IF($Q17=0,0,($AG17+$Z17)/$Q17/IF($P17="USD",INDEX('COD Network Fees'!$B$27:$B$29,MATCH($T17,'COD Network Fees'!$A$27:$A$29,0)),1))) | AL17: =IF($AM17="","",IF($X17*$V17=0,0,$AG17/($X17*$V17))) | AM17: =IF($B17="","",MATCH($B17,'COD Network Fees'!$A$5:$A$23,0))
T18: =IF($AM18="","",INDEX('COD Network Fees'!$C$5:$C$23,$AM18)) | U18: =IF($AM18="","",IF(($K18+$L18+$M18)=0,0,(($E18+$H18)*$K18+($F18+$I18)*$L18+($G18+$J18)*$M18)/($K18+$L18+$M18))) | V18: =IF($AM18="","",IF(($K18+$L18+$M18)=0,0,(Calculator!$H$7*$K18+Calculator!$H$8*$L18+Calculator!$H$9*$M18)/($K18+$L18+$M18))) | W18: =IF($AM18="","",$Q18*$R18) | X18: =IF($AM18="","",$W18*(1-$S18)) | Y18: =IF($AM18="","",$X18*$U18) | Z18: =IF($AM18="","",$Q18*$O18*IF($P18="USD",INDEX('COD Network Fees'!$B$27:$B$29,MATCH($T18,'COD Network Fees'!$A$27:$A$29,0)),1)) | AA18: =IF($AM18="","",$X18*$V18*$N18) | AB18: =IF($AM18="","",IF($D18="Yes",1,0)*($Q18*IF($C18="Cosmetic",INDEX('COD Network Fees'!$G$5:$G$23,$AM18),INDEX('COD Network Fees'!$D$5:$D$23,$AM18))+$W18*IF($C18="Cosmetic",INDEX('COD Network Fees'!$H$5:$H$23,$AM18),INDEX('COD Network Fees'!$E$5:$E$23,$AM18))+$X18*IF($C18="Cosmetic",INDEX('COD Network Fees'!$I$5:$I$23,$AM18),INDEX('COD Network Fees'!$F$5:$F$23,$AM18)))) | AC18: =IF($AM18="","",$X18*IF(AND($D18="No",INDEX('COD Network Fees'!$M$5:$M$23,$AM18)<>""),INDEX('COD Network Fees'!$M$5:$M$23,$AM18),INDEX('COD Network Fees'!$K$5:$K$23,$AM18))+($W18-$X18)*IF(AND($D18="No",INDEX('COD Network Fees'!$M$5:$M$23,$AM18)<>""),INDEX('COD Network Fees'!$M$5:$M$23,$AM18),INDEX('COD Network Fees'!$L$5:$L$23,$AM18))) | AD18: =IF($AM18="","",$W18*INDEX('COD Network Fees'!$N$5:$N$23,$AM18)) | AE18: =IF($AM18="","",$Y18*INDEX('COD Network Fees'!$P$5:$P$23,$AM18)) | AF18: =IF($AM18="","",($Y18-$AB18-$AC18-$AD18-$AE18)*Calculator!$B$19) | AG18: =IF($AM18="","",$Y18-$Z18-$AA18-$AB18-$AC18-$AD18-$AE18-$AF18) | AH18: =IF($AM18="","",IF($X18=0,0,$AG18/$X18)) | AI18: =IF($AM18="","",IF($Y18=0,0,$AG18/$Y18)) | AJ18: =IF($AM18="","",IF(($Z18+$AA18)=0,0,$AG18/($Z18+$AA18))) | AK18: =IF($AM18="","",IF($Q18=0,0,($AG18+$Z18)/$Q18/IF($P18="USD",INDEX('COD Network Fees'!$B$27:$B$29,MATCH($T18,'COD Network Fees'!$A$27:$A$29,0)),1))) | AL18: =IF($AM18="","",IF($X18*$V18=0,0,$AG18/($X18*$V18))) | AM18: =IF($B18="","",MATCH($B18,'COD Network Fees'!$A$5:$A$23,0))
T19: =IF($AM19="","",INDEX('COD Network Fees'!$C$5:$C$23,$AM19)) | U19: =IF($AM19="","",IF(($K19+$L19+$M19)=0,0,(($E19+$H19)*$K19+($F19+$I19)*$L19+($G19+$J19)*$M19)/($K19+$L19+$M19))) | V19: =IF($AM19="","",IF(($K19+$L19+$M19)=0,0,(Calculator!$H$7*$K19+Calculator!$H$8*$L19+Calculator!$H$9*$M19)/($K19+$L19+$M19))) | W19: =IF($AM19="","",$Q19*$R19) | X19: =IF($AM19="","",$W19*(1-$S19)) | Y19: =IF($AM19="","",$X19*$U19) | Z19: =IF($AM19="","",$Q19*$O19*IF($P19="USD",INDEX('COD Network Fees'!$B$27:$B$29,MATCH($T19,'COD Network Fees'!$A$27:$A$29,0)),1)) | AA19: =IF($AM19="","",$X19*$V19*$N19) | AB19: =IF($AM19="","",IF($D19="Yes",1,0)*($Q19*IF($C19="Cosmetic",INDEX('COD Network Fees'!$G$5:$G$23,$AM19),INDEX('COD Network Fees'!$D$5:$D$23,$AM19))+$W19*IF($C19="Cosmetic",INDEX('COD Network Fees'!$H$5:$H$23,$AM19),INDEX('COD Network Fees'!$E$5:$E$23,$AM19))+$X19*IF($C19="Cosmetic",INDEX('COD Network Fees'!$I$5:$I$23,$AM19),INDEX('COD Network Fees'!$F$5:$F$23,$AM19)))) | AC19: =IF($AM19="","",$X19*IF(AND($D19="No",INDEX('COD Network Fees'!$M$5:$M$23,$AM19)<>""),INDEX('COD Network Fees'!$M$5:$M$23,$AM19),INDEX('COD Network Fees'!$K$5:$K$23,$AM19))+($W19-$X19)*IF(AND($D19="No",INDEX('COD Network Fees'!$M$5:$M$23,$AM19)<>""),INDEX('COD Network Fees'!$M$5:$M$23,$AM19),INDEX('COD Network Fees'!$L$5:$L$23,$AM19))) | AD19: =IF($AM19="","",$W19*INDEX('COD Network Fees'!$N$5:$N$23,$AM19)) | AE19: =IF($AM19="","",$Y19*INDEX('COD Network Fees'!$P$5:$P$23,$AM19)) | AF19: =IF($AM19="","",($Y19-$AB19-$AC19-$AD19-$AE19)*Calculator!$B$19) | AG19: =IF($AM19="","",$Y19-$Z19-$AA19-$AB19-$AC19-$AD19-$AE19-$AF19) | AH19: =IF($AM19="","",IF($X19=0,0,$AG19/$X19)) | AI19: =IF($AM19="","",IF($Y19=0,0,$AG19/$Y19)) | AJ19: =IF($AM19="","",IF(($Z19+$AA19)=0,0,$AG19/($Z19+$AA19))) | AK19: =IF($AM19="","",IF($Q19=0,0,($AG19+$Z19)/$Q19/IF($P19="USD",INDEX('COD Network Fees'!$B$27:$B$29,MATCH($T19,'COD Network Fees'!$A$27:$A$29,0)),1))) | AL19: =IF($AM19="","",IF($X19*$V19=0,0,$AG19/($X19*$V19))) | AM19: =IF($B19="","",MATCH($B19,'COD Network Fees'!$A$5:$A$23,0))
... T24: =IF($AM24="","",INDEX('COD Network Fees'!$C$5:$C$23,$AM24)) | U24: =IF($AM24="","",IF(($K24+$L24+$M24)=0,0,(($E24+$H24)*$K24+($F24+$I24)*$L24+($G24+$J24)*$M24)/($K24+$L24+$M24))) | V24: =IF($AM24="","",IF(($K24+$L24+$M24)=0,0,(Calculator!$H$7*$K24+Calculator!$H$8*$L24+Calculator!$H$9*$M24)/($K24+$L24+$M24))) | W24: =IF($AM24="","",$Q24*$R24) | X24: =IF($AM24="","",$W24*(1-$S24)) | Y24: =IF($AM24="","",$X24*$U24) | Z24: =IF($AM24="","",$Q24*$O24*IF($P24="USD",INDEX('COD Network Fees'!$B$27:$B$29,MATCH($T24,'COD Network Fees'!$A$27:$A$29,0)),1)) | AA24: =IF($AM24="","",$X24*$V24*$N24) | AB24: =IF($AM24="","",IF($D24="Yes",1,0)*($Q24*IF($C24="Cosmetic",INDEX('COD Network Fees'!$G$5:$G$23,$AM24),INDEX('COD Network Fees'!$D$5:$D$23,$AM24))+$W24*IF($C24="Cosmetic",INDEX('COD Network Fees'!$H$5:$H$23,$AM24),INDEX('COD Network Fees'!$E$5:$E$23,$AM24))+$X24*IF($C24="Cosmetic",INDEX('COD Network Fees'!$I$5:$I$23,$AM24),INDEX('COD Network Fees'!$F$5:$F$23,$AM24)))) | AC24: =IF($AM24="","",$X24*IF(AND($D24="No",INDEX('COD Network Fees'!$M$5:$M$23,$AM24)<>""),INDEX('COD Network Fees'!$M$5:$M$23,$AM24),INDEX('COD Network Fees'!$K$5:$K$23,$AM24))+($W24-$X24)*IF(AND($D24="No",INDEX('COD Network Fees'!$M$5:$M$23,$AM24)<>""),INDEX('COD Network Fees'!$M$5:$M$23,$AM24),INDEX('COD Network Fees'!$L$5:$L$23,$AM24))) | AD24: =IF($AM24="","",$W24*INDEX('COD Network Fees'!$N$5:$N$23,$AM24)) | AE24: =IF($AM24="","",$Y24*INDEX('COD Network Fees'!$P$5:$P$23,$AM24)) | AF24: =IF($AM24="","",($Y24-$AB24-$AC24-$AD24-$AE24)*Calculator!$B$19) | AG24: =IF($AM24="","",$Y24-$Z24-$AA24-$AB24-$AC24-$AD24-$AE24-$AF24) | AH24: =IF($AM24="","",IF($X24=0,0,$AG24/$X24)) | AI24: =IF($AM24="","",IF($Y24=0,0,$AG24/$Y24)) | AJ24: =IF($AM24="","",IF(($Z24+$AA24)=0,0,$AG24/($Z24+$AA24))) | AK24: =IF($AM24="","",IF($Q24=0,0,($AG24+$Z24)/$Q24/IF($P24="USD",INDEX('COD Network Fees'!$B$27:$B$29,MATCH($T24,'COD Network Fees'!$A$27:$A$29,0)),1))) | AL24: =IF($AM24="","",IF($X24*$V24=0,0,$AG24/($X24*$V24))) | AM24: =IF($B24="","",MATCH($B24,'COD Network Fees'!$A$5:$A$23,0))
A26: All money columns are in each row's market currency (Currency column). Break-even CPL is in the row's CPL currency. Delivery fees are paid by customers on delivered orders only. If the offer % don't add up to 100%, they are scaled to 100%.

Sheet COD Network Fees
A1: COD Network fee schedule (from your agreement)
A2: Source: COD Network DWC LLC agreement (PDF you provided). Blue = values copied from the contract. Edit any cell if your rates change - every calculation updates automatically.
A3: YELLOW = update | B3: Contract rates (no color) - edit only if COD Network changes your prices.
A4: Market | B4: Region | C4: Currency | D4: Lead fee (Gadget) | E4: Confirmed fee (Gadget) | F4: Delivered fee (Gadget) | G4: Lead fee (Cosmetic) | H4: Confirmed fee (Cosmetic) | I4: Delivered fee (Cosmetic) | J4: Upsell / cross-sell fee | K4: Shipping delivered (with call center) | L4: Shipping returned (with call center) | M4: Shipping flat (without call center) | N4: Fulfillment per shipped order | O4: Extra per kg over 5 kg | P4: COD fee (% of collected) | Q4: Notes
A5: UAE | B5: GCC | C5: USD | D5: 0.5 | E5: 1 | F5: 2 | G5: 0.5 | H5: 2 | I5: 3 | J5: 1 | K5: 5.99 | L5: 4.99 | M5: 6.99 | N5: 0 | O5: 1 | P5: 0.05 | Q5: VAT included
A6: KSA | B6: GCC | C6: USD | D6: 0.5 | E6: 1 | F6: 2 | G6: 0.5 | H6: 2 | I6: 3 | J6: 1 | K6: 4.99 | L6: 2.99 | M6: 6.99 | N6: 0 | O6: 1 | P6: 0.05 | Q6: VAT included
A7: Bahrain | B7: GCC | C7: USD | D7: 0.5 | E7: 1 | F7: 2 | G7: 0.5 | H7: 2 | I7: 3 | J7: 1 | K7: 6.99 | L7: 5.99 | M7: 7.99 | N7: 0 | O7: 1 | P7: 0.05 | Q7: VAT included
A8: Oman | B8: GCC | C8: USD | D8: 0.5 | E8: 1 | F8: 2 | G8: 0.5 | H8: 2 | I8: 3 | J8: 1 | K8: 6.99 | L8: 5.99 | M8: 7.99 | N8: 0 | O8: 1 | P8: 0.05 | Q8: VAT included
A9: Kuwait | B9: GCC | C9: USD | D9: 0.5 | E9: 1 | F9: 2 | G9: 0.5 | H9: 2 | I9: 3 | J9: 1 | K9: 6.99 | L9: 5.99 | M9: 7.99 | N9: 0 | O9: 1 | P9: 0.05 | Q9: VAT included
A10: Qatar | B10: GCC | C10: USD | D10: 0.5 | E10: 1 | F10: 2 | G10: 0.5 | H10: 2 | I10: 3 | J10: 1 | K10: 6.99 | L10: 5.99 | M10: 7.99 | N10: 0 | O10: 1 | P10: 0.05 | Q10: VAT included
A11: Morocco | B11: Morocco | C11: MAD | D11: 2 | E11: 4 | F11: 7 | G11: 2 | H11: 4 | I11: 7 | J11: 5 | K11: 35 | L11: 9 | N11: 8 | O11: 0 | P11: 0 | Q11: No COD fee column in the Morocco table - set to 0%. Confirm with COD Network.
A12: Spain | B12: Europe | C12: EUR | D12: 0.5 | E12: 1 | F12: 2 | G12: 0.5 | H12: 1 | I12: 2 | J12: 1 | K12: 7.99 | L12: 6.99 | N12: 0 | O12: 0 | P12: 0.05 | Q12: VAT 0%. Upsell fee not listed for Europe - assumed same as general clause (1).
A13: Portugal | B13: Europe | C13: EUR | D13: 0.5 | E13: 1 | F13: 2 | G13: 0.5 | H13: 1 | I13: 2 | J13: 1 | K13: 7.99 | L13: 8.99 | N13: 0 | O13: 0 | P13: 0.05 | Q13: VAT 0%. Upsell fee not listed for Europe - assumed same as general clause (1).
A14: Poland | B14: Europe | C14: EUR | D14: 0.5 | E14: 1 | F14: 2 | G14: 0.5 | H14: 1 | I14: 2 | J14: 1 | K14: 6.99 | L14: 5.99 | N14: 0 | O14: 0 | P14: 0.05 | Q14: VAT 0%. Upsell fee not listed for Europe - assumed same as general clause (1).
A15: Czech Republic | B15: Europe | C15: EUR | D15: 0.5 | E15: 1 | F15: 2 | G15: 0.5 | H15: 1 | I15: 2 | J15: 1 | K15: 7.99 | L15: 6.99 | N15: 0 | O15: 0 | P15: 0.05 | Q15: VAT 0%. Upsell fee not listed for Europe - assumed same as general clause (1).
A16: Hungary | B16: Europe | C16: EUR | D16: 0.5 | E16: 1 | F16: 2 | G16: 0.5 | H16: 1 | I16: 2 | J16: 1 | K16: 7.99 | L16: 6.99 | N16: 0 | O16: 0 | P16: 0.05 | Q16: VAT 0%. Upsell fee not listed for Europe - assumed same as general clause (1).
A17: Slovakia | B17: Europe | C17: EUR | D17: 0.5 | E17: 1 | F17: 2 | G17: 0.5 | H17: 1 | I17: 2 | J17: 1 | K17: 7.99 | L17: 6.99 | N17: 0 | O17: 0 | P17: 0.05 | Q17: VAT 0%. Upsell fee not listed for Europe - assumed same as general clause (1).
A18: Romania | B18: Europe | C18: EUR | D18: 0.5 | E18: 1 | F18: 2 | G18: 0.5 | H18: 1 | I18: 2 | J18: 1 | K18: 7.99 | L18: 6.99 | N18: 0 | O18: 0 | P18: 0.05 | Q18: VAT 0%. Upsell fee not listed for Europe - assumed same as general clause (1).
A19: Lithuania | B19: Europe | C19: EUR | D19: 0.5 | E19: 1 | F19: 2 | G19: 0.5 | H19: 1 | I19: 2 | J19: 1 | K19: 7.99 | L19: 6.99 | N19: 0 | O19: 0 | P19: 0.05 | Q19: VAT 0%. Upsell fee not listed for Europe - assumed same as general clause (1).
A20: Slovenia | B20: Europe | C20: EUR | D20: 0.5 | E20: 1 | F20: 2 | G20: 0.5 | H20: 1 | I20: 2 | J20: 1 | K20: 7.99 | L20: 6.99 | N20: 0 | O20: 0 | P20: 0.05 | Q20: VAT 0%. Upsell fee not listed for Europe - assumed same as general clause (1).
A21: Croatia | B21: Europe | C21: EUR | D21: 0.5 | E21: 1 | F21: 2 | G21: 0.5 | H21: 1 | I21: 2 | J21: 1 | K21: 7.99 | L21: 6.99 | N21: 0 | O21: 0 | P21: 0.05 | Q21: VAT 0%. Upsell fee not listed for Europe - assumed same as general clause (1).
A22: Colombia | B22: LATAM | C22: USD | D22: 0.25 | E22: 0.5 | F22: 1 | G22: 0.25 | H22: 0.5 | I22: 1 | J22: 1 | K22: 4.49 | L22: 4.49 | N22: 0 | O22: 0 | P22: 0.05 | Q22: VAT 0%. Upsell fee not listed for LATAM - assumed same as general clause ($1).
A23: Panama | B23: LATAM | C23: USD | D23: 0.25 | E23: 0.5 | F23: 1 | G23: 0.25 | H23: 0.5 | I23: 1 | J23: 1 | K23: 7.99 | L23: 7.99 | N23: 0 | O23: 0 | P23: 0.05 | Q23: VAT 0%. Upsell fee not listed for LATAM - assumed same as general clause ($1).
A25: Exchange rates (edit to today's rate)
A26: Currency | B26: Units per 1 USD
A27: USD | B27: 1 | C27: Approximate rates - update them before using. Only used when your cost per result is in USD.
A28: MAD | B28: 9.2
A29: EUR | B29: 0.87
A31: Contract terms that are NOT modelled per order (add them under 'Other fixed costs' on the Calculator if they apply):
A32: - Payment processing on remittances: 0% to 5% depending on method (PayPal, bank transfer, Payoneer) -> input on Calculator.
A33: - International (cross-border) shipping, customs clearance (+$9 Kuwait), import duties and government taxes.
A34: - Storage and labeling are free in all listed markets; GCC fulfillment is free; Morocco fulfillment is 8 MAD per order.
A35: - Volumetric weight: L x H x W / 5000. Use the higher of real and volumetric weight in 'Package weight'.
